Workbook

Sheet Dashboard
A1: HELIOS — Distribuzione task
A3: Stato | B3: Pre-GO (Fasi 1–4) | C3: Post-GO (Fasi 5–12) | D3: Totale
A4: Fatto | B4: =COUNTIF('Pre-GO'!I5:I25,A4) | C4: =COUNTIF('Post-GO'!I5:I53,A4) | D4: =B4+C4
A5: In corso | B5: =COUNTIF('Pre-GO'!I5:I25,A5) | C5: =COUNTIF('Post-GO'!I5:I53,A5) | D5: =B5+C5
A6: In review | B6: =COUNTIF('Pre-GO'!I5:I25,A6) | C6: =COUNTIF('Post-GO'!I5:I53,A6) | D6: =B6+C6
A7: Da fare | B7: =COUNTIF('Pre-GO'!I5:I25,A7) | C7: =COUNTIF('Post-GO'!I5:I53,A7) | D7: =B7+C7
A8: Bloccato | B8: =COUNTIF('Pre-GO'!I5:I25,A8) | C8: =COUNTIF('Post-GO'!I5:I53,A8) | D8: =B8+C8
A9: Totale | B9: =SUM(B4:B8) | C9: =SUM(C4:C8) | D9: =SUM(D4:D8)
A10: % completamento | B10: =IF(B9=0,0,B4/B9) | C10: =IF(C9=0,0,C4/C9) | D10: =IF(D9=0,0,D4/D9)
A13: Assegnato a | B13: Pre-GO | C13: Post-GO | D13: Totale | E13: Di cui fatti
A14: NARO | B14: =COUNTIF('Pre-GO'!K5:K25,A14) | C14: =COUNTIF('Post-GO'!K5:K53,A14) | D14: =B14+C14 | E14: =COUNTIFS('Pre-GO'!K5:K25,A14,'Pre-GO'!I5:I25,"Fatto")+COUNTIFS('Post-GO'!K5:K53,A14,'Post-GO'!I5:I53,"Fatto")
A15: SCIBETTA | B15: =COUNTIF('Pre-GO'!K5:K25,A15) | C15: =COUNTIF('Post-GO'!K5:K53,A15) | D15: =B15+C15 | E15: =COUNTIFS('Pre-GO'!K5:K25,A15,'Pre-GO'!I5:I25,"Fatto")+COUNTIFS('Post-GO'!K5:K53,A15,'Post-GO'!I5:I53,"Fatto")
A16: SUPERVISORE | B16: =COUNTIF('Pre-GO'!K5:K25,A16) | C16: =COUNTIF('Post-GO'!K5:K53,A16) | D16: =B16+C16 | E16: =COUNTIFS('Pre-GO'!K5:K25,A16,'Pre-GO'!I5:I25,"Fatto")+COUNTIFS('Post-GO'!K5:K53,A16,'Post-GO'!I5:I53,"Fatto")
A17: Da assegnare | B17: =COUNTIF('Pre-GO'!K5:K25,A17) | C17: =COUNTIF('Post-GO'!K5:K53,A17) | D17: =B17+C17 | E17: =COUNTIFS('Pre-GO'!K5:K25,A17,'Pre-GO'!I5:I25,"Fatto")+COUNTIFS('Post-GO'!K5:K53,A17,'Post-GO'!I5:I53,"Fatto")
A20: Pacchetto | B20: Task | C20: Fatti | D20: In corso | E20: Da fare | F20: %
A21: PK-00 · Discovery (ADR, Costituzione, runtime) | B21: =COUNTIF('Pre-GO'!D5:D25,"PK-00")+COUNTIF('Post-GO'!D5:D53,"PK-00") | C21: =COUNTIFS('Pre-GO'!D5:D25,"PK-00",'Pre-GO'!I5:I25,"Fatto")+COUNTIFS('Post-GO'!D5:D53,"PK-00",'Post-GO'!I5:I53,"Fatto") | D21: =COUNTIFS('Pre-GO'!D5:D25,"PK-00",'Pre-GO'!I5:I25,"In corso")+COUNTIFS('Post-GO'!D5:D53,"PK-00",'Post-GO'!I5:I53,"In corso") | E21: =COUNTIFS('Pre-GO'!D5:D25,"PK-00",'Pre-GO'!I5:I25,"Da fare")+COUNTIFS('Post-GO'!D5:D53,"PK-00",'Post-GO'!I5:I53,"Da fare") | F21: =IF(B21=0,0,C21/B21)
A22: PK-01 · Contratti JSON | B22: =COUNTIF('Pre-GO'!D5:D25,"PK-01")+COUNTIF('Post-GO'!D5:D53,"PK-01") | C22: =COUNTIFS('Pre-GO'!D5:D25,"PK-01",'Pre-GO'!I5:I25,"Fatto")+COUNTIFS('Post-GO'!D5:D53,"PK-01",'Post-GO'!I5:I53,"Fatto") | D22: =COUNTIFS('Pre-GO'!D5:D25,"PK-01",'Pre-GO'!I5:I25,"In corso")+COUNTIFS('Post-GO'!D5:D53,"PK-01",'Post-GO'!I5:I53,"In corso") | E22: =COUNTIFS('Pre-GO'!D5:D25,"PK-01",'Pre-GO'!I5:I25,"Da fare")+COUNTIFS('Post-GO'!D5:D53,"PK-01",'Post-GO'!I5:I53,"Da fare") | F22: =IF(B22=0,0,C22/B22)
A23: PK-02 · Inventario e ledger ECC | B23: =COUNTIF('Pre-GO'!D5:D25,"PK-02")+COUNTIF('Post-GO'!D5:D53,"PK-02") | C23: =COUNTIFS('Pre-GO'!D5:D25,"PK-02",'Pre-GO'!I5:I25,"Fatto")+COUNTIFS('Post-GO'!D5:D53,"PK-02",'Post-GO'!I5:I53,"Fatto") | D23: =COUNTIFS('Pre-GO'!D5:D25,"PK-02",'Pre-GO'!I5:I25,"In corso")+COUNTIFS('Post-GO'!D5:D53,"PK-02",'Post-GO'!I5:I53,"In corso") | E23: =COUNTIFS('Pre-GO'!D5:D25,"PK-02",'Pre-GO'!I5:I25,"Da fare")+COUNTIFS('Post-GO'!D5:D53,"PK-02",'Post-GO'!I5:I53,"Da fare") | F23: =IF(B23=0,0,C23/B23)
A24: PK-03 · Revisione asset e matrice catena | B24: =COUNTIF('Pre-GO'!D5:D25,"PK-03")+COUNTIF('Post-GO'!D5:D53,"PK-03") | C24: =COUNTIFS('Pre-GO'!D5:D25,"PK-03",'Pre-GO'!I5:I25,"Fatto")+COUNTIFS('Post-GO'!D5:D53,"PK-03",'Post-GO'!I5:I53,"Fatto") | D24: =COUNTIFS('Pre-GO'!D5:D25,"PK-03",'Pre-GO'!I5:I25,"In corso")+COUNTIFS('Post-GO'!D5:D53,"PK-03",'Post-GO'!I5:I53,"In corso") | E24: =COUNTIFS('Pre-GO'!D5:D25,"PK-03",'Pre-GO'!I5:I25,"Da fare")+COUNTIFS('Post-GO'!D5:D53,"PK-03",'Post-GO'!I5:I53,"Da fare") | F24: =IF(B24=0,0,C24/B24)
A25: PK-04 · Import LIMET/CEREBRO nel monorepo (azione del SUPERVISORE) | B25: =COUNTIF('Pre-GO'!D5:D25,"PK-04")+COUNTIF('Post-GO'!D5:D53,"PK-04") | C25: =COUNTIFS('Pre-GO'!D5:D25,"PK-04",'Pre-GO'!I5:I25,"Fatto")+COUNTIFS('Post-GO'!D5:D53,"PK-04",'Post-GO'!I5:I53,"Fatto") | D25: =COUNTIFS('Pre-GO'!D5:D25,"PK-04",'Pre-GO'!I5:I25,"In corso")+COUNTIFS('Post-GO'!D5:D53,"PK-04",'Post-GO'!I5:I53,"In corso") | E25: =COUNTIFS('Pre-GO'!D5:D25,"PK-04",'Pre-GO'!I5:I25,"Da fare")+COUNTIFS('Post-GO'!D5:D53,"PK-04",'Post-GO'!I5:I53,"Da fare") | F25: =IF(B25=0,0,C25/B25)
A26: PK-05 · CI a matrice (3 OS) | B26: =COUNTIF('Pre-GO'!D5:D25,"PK-05")+COUNTIF('Post-GO'!D5:D53,"PK-05") | C26: =COUNTIFS('Pre-GO'!D5:D25,"PK-05",'Pre-GO'!I5:I25,"Fatto")+COUNTIFS('Post-GO'!D5:D53,"PK-05",'Post-GO'!I5:I53,"Fatto") | D26: =COUNTIFS('Pre-GO'!D5:D25,"PK-05",'Pre-GO'!I5:I25,"In corso")+COUNTIFS('Post-GO'!D5:D53,"PK-05",'Post-GO'!I5:I53,"In corso") | E26: =COUNTIFS('Pre-GO'!D5:D25,"PK-05",'Pre-GO'!I5:I25,"Da fare")+COUNTIFS('Post-GO'!D5:D53,"PK-05",'Post-GO'!I5:I53,"Da fare") | F26: =IF(B26=0,0,C26/B26)
A27: PK-05b · Segreti fuori dal repo | B27: =COUNTIF('Pre-GO'!D5:D25,"PK-05b")+COUNTIF('Post-GO'!D5:D53,"PK-05b") | C27: =COUNTIFS('Pre-GO'!D5:D25,"PK-05b",'Pre-GO'!I5:I25,"Fatto")+COUNTIFS('Post-GO'!D5:D53,"PK-05b",'Post-GO'!I5:I53,"Fatto") | D27: =COUNTIFS('Pre-GO'!D5:D25,"PK-05b",'Pre-GO'!I5:I25,"In corso")+COUNTIFS('Post-GO'!D5:D53,"PK-05b",'Post-GO'!I5:I53,"In corso") | E27: =COUNTIFS('Pre-GO'!D5:D25,"PK-05b",'Pre-GO'!I5:I25,"Da fare")+COUNTIFS('Post-GO'!D5:D53,"PK-05b",'Post-GO'!I5:I53,"Da fare") | F27: =IF(B27=0,0,C27/B27)
A28: PK-06 · Shim compat e test confini | B28: =COUNTIF('Pre-GO'!D5:D25,"PK-06")+COUNTIF('Post-GO'!D5:D53,"PK-06") | C28: =COUNTIFS('Pre-GO'!D5:D25,"PK-06",'Pre-GO'!I5:I25,"Fatto")+COUNTIFS('Post-GO'!D5:D53,"PK-06",'Post-GO'!I5:I53,"Fatto") | D28: =COUNTIFS('Pre-GO'!D5:D25,"PK-06",'Pre-GO'!I5:I25,"In corso")+COUNTIFS('Post-GO'!D5:D53,"PK-06",'Post-GO'!I5:I53,"In corso") | E28: =COUNTIFS('Pre-GO'!D5:D25,"PK-06",'Pre-GO'!I5:I25,"Da fare")+COUNTIFS('Post-GO'!D5:D53,"PK-06",'Post-GO'!I5:I53,"Da fare") | F28: =IF(B28=0,0,C28/B28)
A29: PK-07 · Correzione percorso CEREBRO in CLAUDE.md | B29: =COUNTIF('Pre-GO'!D5:D25,"PK-07")+COUNTIF('Post-GO'!D5:D53,"PK-07") | C29: =COUNTIFS('Pre-GO'!D5:D25,"PK-07",'Pre-GO'!I5:I25,"Fatto")+COUNTIFS('Post-GO'!D5:D53,"PK-07",'Post-GO'!I5:I53,"Fatto") | D29: =COUNTIFS('Pre-GO'!D5:D25,"PK-07",'Pre-GO'!I5:I25,"In corso")+COUNTIFS('Post-GO'!D5:D53,"PK-07",'Post-GO'!I5:I53,"In corso") | E29: =COUNTIFS('Pre-GO'!D5:D25,"PK-07",'Pre-GO'!I5:I25,"Da fare")+COUNTIFS('Post-GO'!D5:D53,"PK-07",'Post-GO'!I5:I53,"Da fare") | F29: =IF(B29=0,0,C29/B29)
A30: PK-08 · Runner con allowlist e policy permessi | B30: =COUNTIF('Pre-GO'!D5:D25,"PK-08")+COUNTIF('Post-GO'!D5:D53,"PK-08") | C30: =COUNTIFS('Pre-GO'!D5:D25,"PK-08",'Pre-GO'!I5:I25,"Fatto")+COUNTIFS('Post-GO'!D5:D53,"PK-08",'Post-GO'!I5:I53,"Fatto") | D30: =COUNTIFS('Pre-GO'!D5:D25,"PK-08",'Pre-GO'!I5:I25,"In corso")+COUNTIFS('Post-GO'!D5:D53,"PK-08",'Post-GO'!I5:I53,"In corso") | E30: =COUNTIFS('Pre-GO'!D5:D25,"PK-08",'Pre-GO'!I5:I25,"Da fare")+COUNTIFS('Post-GO'!D5:D53,"PK-08",'Post-GO'!I5:I53,"Da fare") | F30: =IF(B30=0,0,C30/B30)
A31: PK-09 · Ruoli PoC (analyst, developer, reviewer) | B31: =COUNTIF('Pre-GO'!D5:D25,"PK-09")+COUNTIF('Post-GO'!D5:D53,"PK-09") | C31: =COUNTIFS('Pre-GO'!D5:D25,"PK-09",'Pre-GO'!I5:I25,"Fatto")+COUNTIFS('Post-GO'!D5:D53,"PK-09",'Post-GO'!I5:I53,"Fatto") | D31: =COUNTIFS('Pre-GO'!D5:D25,"PK-09",'Pre-GO'!I5:I25,"In corso")+COUNTIFS('Post-GO'!D5:D53,"PK-09",'Post-GO'!I5:I53,"In corso") | E31: =COUNTIFS('Pre-GO'!D5:D25,"PK-09",'Pre-GO'!I5:I25,"Da fare")+COUNTIFS('Post-GO'!D5:D53,"PK-09",'Post-GO'!I5:I53,"Da fare") | F31: =IF(B31=0,0,C31/B31)
A32: PK-10 · Gate umano meccanico sul PLAN | B32: =COUNTIF('Pre-GO'!D5:D25,"PK-10")+COUNTIF('Post-GO'!D5:D53,"PK-10") | C32: =COUNTIFS('Pre-GO'!D5:D25,"PK-10",'Pre-GO'!I5:I25,"Fatto")+COUNTIFS('Post-GO'!D5:D53,"PK-10",'Post-GO'!I5:I53,"Fatto") | D32: =COUNTIFS('Pre-GO'!D5:D25,"PK-10",'Pre-GO'!I5:I25,"In corso")+COUNTIFS('Post-GO'!D5:D53,"PK-10",'Post-GO'!I5:I53,"In corso") | E32: =COUNTIFS('Pre-GO'!D5:D25,"PK-10",'Pre-GO'!I5:I25,"Da fare")+COUNTIFS('Post-GO'!D5:D53,"PK-10",'Post-GO'!I5:I53,"Da fare") | F32: =IF(B32=0,0,C32/B32)
A33: PK-11 · Prova del plugin Claude Code (V13/V14) | B33: =COUNTIF('Pre-GO'!D5:D25,"PK-11")+COUNTIF('Post-GO'!D5:D53,"PK-11") | C33: =COUNTIFS('Pre-GO'!D5:D25,"PK-11",'Pre-GO'!I5:I25,"Fatto")+COUNTIFS('Post-GO'!D5:D53,"PK-11",'Post-GO'!I5:I53,"Fatto") | D33: =COUNTIFS('Pre-GO'!D5:D25,"PK-11",'Pre-GO'!I5:I25,"In corso")+COUNTIFS('Post-GO'!D5:D53,"PK-11",'Post-GO'!I5:I53,"In corso") | E33: =COUNTIFS('Pre-GO'!D5:D25,"PK-11",'Pre-GO'!I5:I25,"Da fare")+COUNTIFS('Post-GO'!D5:D53,"PK-11",'Post-GO'!I5:I53,"Da fare") | F33: =IF(B33=0,0,C33/B33)
A34: PK-12 · Asset ECC portato + A/B | B34: =COUNTIF('Pre-GO'!D5:D25,"PK-12")+COUNTIF('Post-GO'!D5:D53,"PK-12") | C34: =COUNTIFS('Pre-GO'!D5:D25,"PK-12",'Pre-GO'!I5:I25,"Fatto")+COUNTIFS('Post-GO'!D5:D53,"PK-12",'Post-GO'!I5:I53,"Fatto") | D34: =COUNTIFS('Pre-GO'!D5:D25,"PK-12",'Pre-GO'!I5:I25,"In corso")+COUNTIFS('Post-GO'!D5:D53,"PK-12",'Post-GO'!I5:I53,"In corso") | E34: =COUNTIFS('Pre-GO'!D5:D25,"PK-12",'Pre-GO'!I5:I25,"Da fare")+COUNTIFS('Post-GO'!D5:D53,"PK-12",'Post-GO'!I5:I53,"Da fare") | F34: =IF(B34=0,0,C34/B34)
A35: PK-13 · Rapporto go/no-go (compila NARO, decide il SUPERVISORE) | B35: =COUNTIF('Pre-GO'!D5:D25,"PK-13")+COUNTIF('Post-GO'!D5:D53,"PK-13") | C35: =COUNTIFS('Pre-GO'!D5:D25,"PK-13",'Pre-GO'!I5:I25,"Fatto")+COUNTIFS('Post-GO'!D5:D53,"PK-13",'Post-GO'!I5:I53,"Fatto") | D35: =COUNTIFS('Pre-GO'!D5:D25,"PK-13",'Pre-GO'!I5:I25,"In corso")+COUNTIFS('Post-GO'!D5:D53,"PK-13",'Post-GO'!I5:I53,"In corso") | E35: =COUNTIFS('Pre-GO'!D5:D25,"PK-13",'Pre-GO'!I5:I25,"Da fare")+COUNTIFS('Post-GO'!D5:D53,"PK-13",'Post-GO'!I5:I53,"Da fare") | F35: =IF(B35=0,0,C35/B35)
A36: PK-14 · Contratti della catena e skill runner | B36: =COUNTIF('Pre-GO'!D5:D25,"PK-14")+COUNTIF('Post-GO'!D5:D53,"PK-14") | C36: =COUNTIFS('Pre-GO'!D5:D25,"PK-14",'Pre-GO'!I5:I25,"Fatto")+COUNTIFS('Post-GO'!D5:D53,"PK-14",'Post-GO'!I5:I53,"Fatto") | D36: =COUNTIFS('Pre-GO'!D5:D25,"PK-14",'Pre-GO'!I5:I25,"In corso")+COUNTIFS('Post-GO'!D5:D53,"PK-14",'Post-GO'!I5:I53,"In corso") | E36: =COUNTIFS('Pre-GO'!D5:D25,"PK-14",'Pre-GO'!I5:I25,"Da fare")+COUNTIFS('Post-GO'!D5:D53,"PK-14",'Post-GO'!I5:I53,"Da fare") | F36: =IF(B36=0,0,C36/B36)
A37: PK-15 · Scheduler e regole comuni dei ruoli | B37: =COUNTIF('Pre-GO'!D5:D25,"PK-15")+COUNTIF('Post-GO'!D5:D53,"PK-15") | C37: =COUNTIFS('Pre-GO'!D5:D25,"PK-15",'Pre-GO'!I5:I25,"Fatto")+COUNTIFS('Post-GO'!D5:D53,"PK-15",'Post-GO'!I5:I53,"Fatto") | D37: =COUNTIFS('Pre-GO'!D5:D25,"PK-15",'Pre-GO'!I5:I25,"In corso")+COUNTIFS('Post-GO'!D5:D53,"PK-15",'Post-GO'!I5:I53,"In corso") | E37: =COUNTIFS('Pre-GO'!D5:D25,"PK-15",'Pre-GO'!I5:I25,"Da fare")+COUNTIFS('Post-GO'!D5:D53,"PK-15",'Post-GO'!I5:I53,"Da fare") | F37: =IF(B37=0,0,C37/B37)
A38: PK-16 · Porting asset ECC | B38: =COUNTIF('Pre-GO'!D5:D25,"PK-16")+COUNTIF('Post-GO'!D5:D53,"PK-16") | C38: =COUNTIFS('Pre-GO'!D5:D25,"PK-16",'Pre-GO'!I5:I25,"Fatto")+COUNTIFS('Post-GO'!D5:D53,"PK-16",'Post-GO'!I5:I53,"Fatto") | D38: =COUNTIFS('Pre-GO'!D5:D25,"PK-16",'Pre-GO'!I5:I25,"In corso")+COUNTIFS('Post-GO'!D5:D53,"PK-16",'Post-GO'!I5:I53,"In corso") | E38: =COUNTIFS('Pre-GO'!D5:D25,"PK-16",'Pre-GO'!I5:I25,"Da fare")+COUNTIFS('Post-GO'!D5:D53,"PK-16",'Post-GO'!I5:I53,"Da fare") | F38: =IF(B38=0,0,C38/B38)
A39: PK-17 · Ruoli di sviluppo | B39: =COUNTIF('Pre-GO'!D5:D25,"PK-17")+COUNTIF('Post-GO'!D5:D53,"PK-17") | C39: =COUNTIFS('Pre-GO'!D5:D25,"PK-17",'Pre-GO'!I5:I25,"Fatto")+COUNTIFS('Post-GO'!D5:D53,"PK-17",'Post-GO'!I5:I53,"Fatto") | D39: =COUNTIFS('Pre-GO'!D5:D25,"PK-17",'Pre-GO'!I5:I25,"In corso")+COUNTIFS('Post-GO'!D5:D53,"PK-17",'Post-GO'!I5:I53,"In corso") | E39: =COUNTIFS('Pre-GO'!D5:D25,"PK-17",'Pre-GO'!I5:I25,"Da fare")+COUNTIFS('Post-GO'!D5:D53,"PK-17",'Post-GO'!I5:I53,"Da fare") | F39: =IF(B39=0,0,C39/B39)
A40: PK-18 · Ruoli di controllo | B40: =COUNTIF('Pre-GO'!D5:D25,"PK-18")+COUNTIF('Post-GO'!D5:D53,"PK-18") | C40: =COUNTIFS('Pre-GO'!D5:D25,"PK-18",'Pre-GO'!I5:I25,"Fatto")+COUNTIFS('Post-GO'!D5:D53,"PK-18",'Post-GO'!I5:I53,"Fatto") | D40: =COUNTIFS('Pre-GO'!D5:D25,"PK-18",'Pre-GO'!I5:I25,"In corso")+COUNTIFS('Post-GO'!D5:D53,"PK-18",'Post-GO'!I5:I53,"In corso") | E40: =COUNTIFS('Pre-GO'!D5:D25,"PK-18",'Pre-GO'!I5:I25,"Da fare")+COUNTIFS('Post-GO'!D5:D53,"PK-18",'Post-GO'!I5:I53,"Da fare") | F40: =IF(B40=0,0,C40/B40)
A41: PK-19 · Workflow core e permessi tool | B41: =COUNTIF('Pre-GO'!D5:D25,"PK-19")+COUNTIF('Post-GO'!D5:D53,"PK-19") | C41: =COUNTIFS('Pre-GO'!D5:D25,"PK-19",'Pre-GO'!I5:I25,"Fatto")+COUNTIFS('Post-GO'!D5:D53,"PK-19",'Post-GO'!I5:I53,"Fatto") | D41: =COUNTIFS('Pre-GO'!D5:D25,"PK-19",'Pre-GO'!I5:I25,"In corso")+COUNTIFS('Post-GO'!D5:D53,"PK-19",'Post-GO'!I5:I53,"In corso") | E41: =COUNTIFS('Pre-GO'!D5:D25,"PK-19",'Pre-GO'!I5:I25,"Da fare")+COUNTIFS('Post-GO'!D5:D53,"PK-19",'Post-GO'!I5:I53,"Da fare") | F41: =IF(B41=0,0,C41/B41)
A42: PK-20 · Stato/eventi, report e gate di merge | B42: =COUNTIF('Pre-GO'!D5:D25,"PK-20")+COUNTIF('Post-GO'!D5:D53,"PK-20") | C42: =COUNTIFS('Pre-GO'!D5:D25,"PK-20",'Pre-GO'!I5:I25,"Fatto")+COUNTIFS('Post-GO'!D5:D53,"PK-20",'Post-GO'!I5:I53,"Fatto") | D42: =COUNTIFS('Pre-GO'!D5:D25,"PK-20",'Pre-GO'!I5:I25,"In corso")+COUNTIFS('Post-GO'!D5:D53,"PK-20",'Post-GO'!I5:I53,"In corso") | E42: =COUNTIFS('Pre-GO'!D5:D25,"PK-20",'Pre-GO'!I5:I25,"Da fare")+COUNTIFS('Post-GO'!D5:D53,"PK-20",'Post-GO'!I5:I53,"Da fare") | F42: =IF(B42=0,0,C42/B42)
A43: PK-21 · Valutazione rischi di prodotto (C28) | B43: =COUNTIF('Pre-GO'!D5:D25,"PK-21")+COUNTIF('Post-GO'!D5:D53,"PK-21") | C43: =COUNTIFS('Pre-GO'!D5:D25,"PK-21",'Pre-GO'!I5:I25,"Fatto")+COUNTIFS('Post-GO'!D5:D53,"PK-21",'Post-GO'!I5:I53,"Fatto") | D43: =COUNTIFS('Pre-GO'!D5:D25,"PK-21",'Pre-GO'!I5:I25,"In corso")+COUNTIFS('Post-GO'!D5:D53,"PK-21",'Post-GO'!I5:I53,"In corso") | E43: =COUNTIFS('Pre-GO'!D5:D25,"PK-21",'Pre-GO'!I5:I25,"Da fare")+COUNTIFS('Post-GO'!D5:D53,"PK-21",'Post-GO'!I5:I53,"Da fare") | F43: =IF(B43=0,0,C43/B43)
A44: PK-22 · Installer e modifiche documentali a LIMET | B44: =COUNTIF('Pre-GO'!D5:D25,"PK-22")+COUNTIF('Post-GO'!D5:D53,"PK-22") | C44: =COUNTIFS('Pre-GO'!D5:D25,"PK-22",'Pre-GO'!I5:I25,"Fatto")+COUNTIFS('Post-GO'!D5:D53,"PK-22",'Post-GO'!I5:I53,"Fatto") | D44: =COUNTIFS('Pre-GO'!D5:D25,"PK-22",'Pre-GO'!I5:I25,"In corso")+COUNTIFS('Post-GO'!D5:D53,"PK-22",'Post-GO'!I5:I53,"In corso") | E44: =COUNTIFS('Pre-GO'!D5:D25,"PK-22",'Pre-GO'!I5:I25,"Da fare")+COUNTIFS('Post-GO'!D5:D53,"PK-22",'Post-GO'!I5:I53,"Da fare") | F44: =IF(B44=0,0,C44/B44)
A45: PK-23 · Hook ECC e registro chiamate LLM | B45: =COUNTIF('Pre-GO'!D5:D25,"PK-23")+COUNTIF('Post-GO'!D5:D53,"PK-23") | C45: =COUNTIFS('Pre-GO'!D5:D25,"PK-23",'Pre-GO'!I5:I25,"Fatto")+COUNTIFS('Post-GO'!D5:D53,"PK-23",'Post-GO'!I5:I53,"Fatto") | D45: =COUNTIFS('Pre-GO'!D5:D25,"PK-23",'Pre-GO'!I5:I25,"In corso")+COUNTIFS('Post-GO'!D5:D53,"PK-23",'Post-GO'!I5:I53,"In corso") | E45: =COUNTIFS('Pre-GO'!D5:D25,"PK-23",'Pre-GO'!I5:I25,"Da fare")+COUNTIFS('Post-GO'!D5:D53,"PK-23",'Post-GO'!I5:I53,"Da fare") | F45: =IF(B45=0,0,C45/B45)
...

Sheet Pre-GO
A1: HELIOS — Distribuzione task · Pre-GO (Fasi 1–4, fino al gate go/no-go)
A2: Avanzamento: | B2: =COUNTIF(I5:I25,"Fatto")/COUNTA(C5:C25) | C2: =COUNTIF(I5:I25,"Fatto")&" fatti / "&COUNTA(C5:C25)&" task · "&COUNTIF(I5:I25,"In corso")&" in corso · "&COUNTIF(I5:I25,"Bloccato")&" bloccati"
A4: Fase | B4: Ordine | C4: ID | D4: Pacchetto | E4: Titolo | F4: Fonte (IN / R05) | G4: Descrizione / contesto | H4: Dipende da | I4: Stato | J4: Già fatto? | K4: Assegnato a | L4: Complessità | M4: Branch di riferimento | N4: Pushato? | O4: Commit (hash) | P4: Inizio | Q4: Fine | R4: Note | S4: % avanzamento | T4: Test T-xxx | U4: Prerequisiti ancora aperti | V4: Percorsi toccati
A5: 1 | B5: 1 | C5: H-101 | D5: PK-00 | E5: ADR fondativo | F5: `docs/adr/0001-helios.md` | G5: Mettere per iscritto owner, perimetro ECC, pin `25278e7`, revoca | H5: — | I5: Fatto | J5: =IF(I5="Fatto","✔ Sì","✘ No") | K5: SUPERVISORE | N5: — | O5: — | R5: **done 2026-10-29 20:07**, approvato dal SUPERVISORE. `docs/` non ancora indicizzata in CEREBRO: aggiunta a cura del SUPERVISORE (scelta 1). C28: nessun rischio rilevato; controlli: coerenza con C01/C04/C06/C07/C08/C09/C11/C14/C28, Q3/Q7, nessun file di input toccato. | S5: 1 | T5: — | U5: — | V5: docs/adr/0001-helios.md
A6: 1 | B6: 2 | C6: H-102 | D6: PK-00 | E6: Costituzione HELIOS | F6: `docs/CONSTITUTION.md` | G6: Raccogliere i non-negoziabili §2.3 compresa la valutazione rischi a fine task (C28) | H6: H-101 [P] | I6: Fatto | J6: =IF(I6="Fatto","✔ Sì","✘ No") | K6: SUPERVISORE | N6: — | O6: — | R6: **done 2026-10-29 20:18**, approvata dal SUPERVISORE. «Richiamata da ogni ruolo»: rinviata alla creazione dei ruoli (H-401/H-402…), non ancora verificabile. C28: nessun rischio rilevato; controlli: 7 regole = IN §2.3 n.1–7, nessun requisito nuovo, nessun file di input toccato. `docs/` non ancora indicizzata (a cura del SUPERVISORE). | S6: 1 | T6: — | U6: — | V6: docs/CONSTITUTION.md
A7: 1 | B7: 3 | C7: H-103 | D7: PK-00 | E7: Conferma runtime e struttura test | F7: `docs/adr/0002-runtime.md` (IN §5 Fase 1, §8 Q4/Q8). Q-11 chiusa per i comandi | G7: Formalizzare Python ≥ 3.11 (Q4) e JS solo scheduler/workflow (Q8); confermare nomi/framework dei test | H7: H-101 [P] | I7: Fatto | J7: =IF(I7="Fatto","✔ Sì","✘ No") | K7: SUPERVISORE | N7: — | O7: — | R7: **done 2026-10-29 20:24**, approvato dal SUPERVISORE. Restano [N] non bloccanti: framework test UI, gestore pacchetti Python. C28: nessun rischio rilevato; controlli: coerenza con IN §3.1/§8 Q4-Q8 e C13, nessun requisito nuovo, nessun file di input toccato. | S7: 1 | T7: — | U7: — | V7: docs/adr/0002-runtime.md
A8: 3 | B8: 4 | C8: H-303 | D8: PK-01 | E8: Contratti §3.3 come schemi JSON | F8: `agents/contracts/*.schema.json` | G8: Definire il linguaggio comune tra ruoli e runner | H8: H-103 | I8: Da fare | J8: =IF(I8="Fatto","✔ Sì","✘ No") | K8: SCIBETTA | N8: — | O8: — | S8: 0 | T8: T-303 | U8: — | V8: agents/contracts/*.schema.json
A9: 2 | B9: 5 | C9: H-201 | D9: PK-02 | E9: Script di inventario ECC | F9: **Fase 2.** `agents/tools/inventory_ecc.py` | G9: Leggere il 100% dei file ECC e contarli | H9: H-101 [P] | I9: Da fare | J9: =IF(I9="Fatto","✔ Sì","✘ No") | K9: NARO | N9: — | O9: — | S9: 0 | T9: T-201 | U9: — | V9: agents/tools/inventory_ecc.py, REGISTRO_SKILLS_AGENTI_ECC.md
A10: 2 | B10: 6 | C10: H-202 | D10: PK-02 | E10: Ledger licenze + allowlist MIT | F10: **Fase 2.** `agents/assets/ecc-ledger.json`, `NOTICE` | G10: Ogni asset con hash/licenza/origine; non-MIT esclusi | H10: H-201 [P] | I10: Da fare | J10: =IF(I10="Fatto","✔ Sì","✘ No") | K10: NARO | N10: — | O10: — | S10: 0 | T10: T-202 | U10: H-201 | V10: agents/assets/ecc-ledger.json
A11: 2 | B11: 7 | C11: H-203 | D11: PK-03 | E11: Revisione manuale asset in allowlist | F11: **Fase 2.** `docs/ecc-review.md` | G11: Checklist firmata su ogni asset ammesso | H11: H-202 [P] | I11: Da fare | J11: =IF(I11="Fatto","✔ Sì","✘ No") | K11: NARO | N11: — | O11: — | S11: 0 | T11: — | U11: H-202 | V11: docs/ecc-review.md
A12: 2 | B12: 8 | C12: H-204 | D12: PK-03 | E12: Matrice catena | F12: **Fase 2.** `docs/chain-matrix.md`, `agents/assets/chain-matrix.json` | G12: Assegnare 71 agenti + 311 skill a un ruolo o escluderli con motivo | H12: H-201, H-202 [P] | I12: Da fare | J12: =IF(I12="Fatto","✔ Sì","✘ No") | K12: NARO | N12: — | O12: — | S12: 0 | T12: T-204 | U12: H-201, H-202 | V12: docs/chain-matrix.md, agents/assets/chain-matrix.json
A13: 3 | B13: 9 | C13: H-301 | D13: PK-04 | E13: Import LIMET e CEREBRO nel monorepo | F13: **Azione del SUPERVISORE** (commit/push). Done: originali invariati (IN §5 Fase 3). **[N]** Q-9 (remote CEREBRO) | G13: Portare `limet/` e `cerebro/` con storia in sottocartelle | H13: H-101 [P] | I13: Da fare | J13: =IF(I13="Fatto","✔ Sì","✘ No") | K13: SUPERVISORE | N13: — | O13: — | S13: 0 | T13: — | U13: — | V13: limet/, cerebro/ (nuove cartelle di import)
A14: 3 | B14: 10 | C14: H-306 | D14: PK-05 | E14: CI a matrice | F14: `.github/workflows/ci.yml` | G14: Stessa suite su windows/ubuntu/macos | H14: H-103 | I14: Da fare | J14: =IF(I14="Fatto","✔ Sì","✘ No") | K14: SCIBETTA | N14: — | O14: — | S14: 0 | T14: T-306 | U14: — | V14: .github/workflows/ci.yml
A15: 3 | B15: 11 | C15: H-302 | D15: PK-05b | E15: Segreti fuori dal repo | F15: Test T-302 | G15: `projects.example.json`, `.gitignore` per `cache/` e dati Qdrant, scansione segreti in CI | H15: H-301 | I15: Da fare | J15: =IF(I15="Fatto","✔ Sì","✘ No") | K15: SCIBETTA | N15: — | O15: — | S15: 0 | T15: T-302 | U15: H-301 | V15: .gitignore, projects.example.json, .github/workflows/ci.yml (scansione segreti)
A16: 3 | B16: 12 | C16: H-304 | D16: PK-06 | E16: Shim `compat/` | F16: T-304 | G16: Mantenere invariati comandi legacy (`cerebro.sh`, `query_qdrant.py`, `ingest_docs.py`, `limet.ps1/.sh`, hook/MCP): stessi argomenti, porte, nomi collection | H16: H-301 | I16: Da fare | J16: =IF(I16="Fatto","✔ Sì","✘ No") | K16: SCIBETTA | N16: — | O16: — | S16: 0 | T16: T-304 | U16: H-301 | V16: compat/, tests/test_module_boundaries.py
A17: 3 | B17: 13 | C17: H-305 | D17: PK-06 | E17: Test dei confini tra moduli | F17: `tests/test_module_boundaries.py` | G17: Evitare dipendenze incrociate non previste | H17: H-301 | I17: Da fare | J17: =IF(I17="Fatto","✔ Sì","✘ No") | K17: SCIBETTA | N17: — | O17: — | S17: 0 | T17: T-305 | U17: H-301 | V17: tests/test_module_boundaries.py
A18: 3 | B18: 14 | C18: H-307 | D18: PK-07 | E18: Correzione percorso CEREBRO in `CLAUDE.md` | F18: Done: nessun riferimento (IN §5 Fase 3) | G18: Eliminare il riferimento `C:\Progetti\CEREBRO` nella copia interna | H18: H-301 | I18: Da fare | J18: =IF(I18="Fatto","✔ Sì","✘ No") | K18: NARO | N18: — | O18: — | S18: 0 | T18: — | U18: H-301 | V18: cerebro/CLAUDE.md [P: copia interna]
A19: 4 | B19: 15 | C19: H-401 | D19: PK-08 | E19: Runner con allowlist | F19: `agents/runner/` | G19: Eseguire solo operazioni ammesse, senza rete, con log hashato, senza commit/push | H19: H-303, H-103 [P] | I19: Da fare | J19: =IF(I19="Fatto","✔ Sì","✘ No") | K19: SCIBETTA | N19: — | O19: — | S19: 0 | T19: T-401, T-402 | U19: H-303 | V19: agents/runner/
... A25: 4 | B25: 21 | C25: H-406 | D25: PK-13 | E25: Rapporto go/no-go | F25: `docs/poc-report.md`. **PUNTO DI DECISIONE del SUPERVISORE (GO / NO-GO / piano B), non fine del piano**: Fasi 5–12 dipendono da questo esito | G25: Giudicare i 10 criteri di R05 §5 | H25: H-401…H-405, H-407 | I25: Da fare | J25: =IF(I25="Fatto","✔ Sì","✘ No") | K25: NARO | N25: — | O25: — | S25: 0 | T25: — | U25: H-401, H-402, H-403, H-404, H-405, H-407 | V25: docs/poc-report.md

Sheet Post-GO
A1: HELIOS — Distribuzione task · Post-GO (Fasi 5–12, solo dopo GO del SUPERVISORE)
A2: Avanzamento: | B2: =COUNTIF(I5:I53,"Fatto")/COUNTA(C5:C53) | C2: =COUNTIF(I5:I53,"Fatto")&" fatti / "&COUNTA(C5:C53)&" task · "&COUNTIF(I5:I53,"In corso")&" in corso · "&COUNTIF(I5:I53,"Bloccato")&" bloccati"
A4: Fase | B4: Ordine | C4: ID | D4: Pacchetto | E4: Titolo | F4: Fonte (IN / R05) | G4: Descrizione / contesto | H4: Dipende da | I4: Stato | J4: Già fatto? | K4: Assegnato a | L4: Complessità | M4: Branch di riferimento | N4: Pushato? | O4: Commit (hash) | P4: Inizio | Q4: Fine | R4: Note | S4: % avanzamento | T4: Test T-xxx | U4: Prerequisiti ancora aperti | V4: Percorsi toccati
A5: 6 | B5: 22 | C5: H-308 | D5: PK-14 | E5: Contratti della catena | F5: **Fasi 5–7, gruppo A.** T-308. **[P]** fase = 6 (contratti dei ruoli) | G5: Schemi `plan/result/findings/verdict/reading/merge/risk`, `state.json`, `events.jsonl`, stati R17 | H5: H-303, H-401 (gruppo A) | I5: Da fare | J5: =IF(I5="Fatto","✔ Sì","✘ No") | K5: SCIBETTA | N5: — | O5: — | R5: Dopo GO | S5: 0 | T5: T-308 | U5: H-303, H-401 · gruppo A/C come da dipendenze | V5: agents/contracts/ (nuovi schemi), agents/plugin/skills/limet-runner/
A6: 6 | B6: 23 | C6: H-409 | D6: PK-14 | E6: Skill `limet-runner` | F6: **Gruppo A.** `agents/plugin/skills/limet-runner/` | G6: Wrapper del runner H-401 verso il workflow | H6: H-303, H-401 (gruppo A) | I6: Da fare | J6: =IF(I6="Fatto","✔ Sì","✘ No") | K6: SCIBETTA | N6: — | O6: — | R6: Dopo GO | S6: 0 | T6: T-409 | U6: H-303, H-401 · gruppo A/C come da dipendenze | V6: agents/plugin/skills/limet-runner/
A7: 7 | B7: 24 | C7: H-408 | D7: PK-15 | E7: Scheduler a funzioni pure (JS) | F7: **Gruppo A.** `agents/plugin/scheduler/limet-scheduler.js` | G7: Decidere cosa parte e quando (onde, budget) | H7: H-303, H-401 (gruppo A) | I7: Da fare | J7: =IF(I7="Fatto","✔ Sì","✘ No") | K7: NARO | N7: — | O7: — | R7: Dopo GO | S7: 0 | T7: T-408 | U7: H-303, H-401 · gruppo A/C come da dipendenze | V7: agents/plugin/scheduler/limet-scheduler.js
A8: 6 | B8: 25 | C8: H-611 | D8: PK-15 | E8: `_common` e rules per ruolo | F8: **Fase 6, gruppo A.** `agents/plugin/agents/_common.md` | G8: Regole condivise dei ruoli, «fermati e chiedi», regole KB §3.8 | H8: H-303, H-401 (gruppo A) | I8: Da fare | J8: =IF(I8="Fatto","✔ Sì","✘ No") | K8: NARO | N8: — | O8: — | R8: Dopo GO | S8: 0 | T8: T-610 | U8: H-303, H-401 · gruppo A/C come da dipendenze | V8: agents/plugin/agents/_common.md
A9: 5 | B9: 26 | C9: H-501 | D9: PK-16 | E9: Test di agnosticità statico | F9: **Fase 5, gruppo B.** T-501 | G9: Nessun hook/tool/memoria/`.claude/plans` negli asset | H9: H-204, H-308 | I9: Da fare | J9: =IF(I9="Fatto","✔ Sì","✘ No") | K9: NARO | N9: — | O9: — | R9: Dopo GO | S9: 0 | T9: T-501 | U9: H-204, H-308 | V9: agents/assets/ (ecc-*), test di agnosticità
A10: 5 | B10: 27 | C10: H-502 | D10: PK-16 | E10: Porting per ruolo di rules e skill | F10: **Fase 5.** T-502 | G10: Asset `ecc-*` con rules per ruolo | H10: H-204, H-308 | I10: Da fare | J10: =IF(I10="Fatto","✔ Sì","✘ No") | K10: NARO | N10: — | O10: — | R10: Dopo GO | S10: 0 | T10: T-502 | U10: H-204, H-308 | V10: agents/assets/ (ecc-*), test di agnosticità
A11: 5 | B11: 28 | C11: H-503 | D11: PK-16 | E11: Nessun file di piano ECC / collisioni | F11: **Fase 5.** T-503. Recepisce la regola dei planner ECC (consulenti in sola lettura) | G11: Proposte in `ecosystem/proposals/`, mai in file di piano | H11: H-204, H-308 | I11: Da fare | J11: =IF(I11="Fatto","✔ Sì","✘ No") | K11: NARO | N11: — | O11: — | R11: Dopo GO | S11: 0 | T11: T-503 | U11: H-204, H-308 | V11: agents/assets/ (ecc-*), test di agnosticità
A12: 6 | B12: 29 | C12: H-602 | D12: PK-17 | E12: Ruolo `analyst` (opus) | F12: **Fase 6, gruppo C.** `agents/plugin/agents/analyst.md` | G12: Produrre `plan.json`; non inventa requisiti | H12: gruppo A, H-402 | I12: Da fare | J12: =IF(I12="Fatto","✔ Sì","✘ No") | K12: SCIBETTA | N12: — | O12: — | R12: Dopo GO | S12: 0 | T12: T-601 | U12: H-402 · gruppo A/C come da dipendenze | V12: agents/plugin/agents/analyst.md
A13: 6 | B13: 30 | C13: H-603 | D13: PK-17 | E13: Ruolo `developer` ×N (sonnet) | F13: **Fase 6.** `developer.md` | G13: Un task per worktree/ramo, mai build/test/push | H13: gruppo A, H-402 | I13: Da fare | J13: =IF(I13="Fatto","✔ Sì","✘ No") | K13: SCIBETTA | N13: — | O13: — | R13: Dopo GO | S13: 0 | T13: T-602 | U13: H-402 · gruppo A/C come da dipendenze | V13: developer.md
A14: 6 | B14: 31 | C14: H-604 | D14: PK-17 | E14: Ruolo `tester` ×M (sonnet) | F14: **Fase 6.** `tester.md` | G14: Test dal TEST_PLAN senza vedere il diff; mai Graphify | H14: gruppo A, H-402 | I14: Da fare | J14: =IF(I14="Fatto","✔ Sì","✘ No") | K14: SCIBETTA | N14: — | O14: — | R14: Dopo GO | S14: 0 | T14: T-603 | U14: H-402 · gruppo A/C come da dipendenze | V14: tester.md
A15: 6 | B15: 32 | C15: H-605 | D15: PK-17 | E15: Ruolo `integrator` (sonnet) | F15: **Fase 6.** `integrator.md` | G15: Integra su `integration/NNNN`; mai merge su `main` | H15: gruppo A, H-402 | I15: Da fare | J15: =IF(I15="Fatto","✔ Sì","✘ No") | K15: SCIBETTA | N15: — | O15: — | R15: Dopo GO | S15: 0 | T15: T-604 | U15: H-402 · gruppo A/C come da dipendenze | V15: integrator.md
A16: 6 | B16: 33 | C16: H-606 | D16: PK-18 | E16: Ruolo `test-reader` (haiku) | F16: **Fase 6.** `test-reader.md` | G16: Classifica i fallimenti con estratti reali | H16: gruppo A, H-402 | I16: Da fare | J16: =IF(I16="Fatto","✔ Sì","✘ No") | K16: NARO | N16: — | O16: — | R16: Dopo GO | S16: 0 | T16: T-605 | U16: H-402 · gruppo A/C come da dipendenze | V16: test-reader.md
... A40: 8 | B40: 57 | C40: H-804 | D40: PK-24 | E40: Accesso agenti alla KB | F40: **Fase 8.** T-804 | G40: Solo MCP/CLI in sola lettura, eventi registrati, degrado senza contesto | H40: H-803, H-611 [P] | I40: Da fare | J40: =IF(I40="Fatto","✔ Sì","✘ No") | K40: SCIBETTA | N40: — | O40: — | R40: Dopo GO | S40: 0 | T40: T-804 | U40: H-611, H-803 | V40: [N] script KB / MCP in sola lettura
A41: 8b | B41: 58 | C41: H-8b01 | D41: PK-25 | E41: `api/` loopback e hardening | F41: **Fase 8b.** T-8b01…T-8b04 | G41: Token, Host/Origin, CSRF, CSP, limite body | H41: H-303, H-401 [P] | I41: Da fare | J41: =IF(I41="Fatto","✔ Sì","✘ No") | K41: SCIBETTA | N41: — | O41: — | R41: Dopo GO | S41: 0 | T41: T-8b01, T-8b04 | U41: H-303, H-401 | V41: api/
A42: 8b | B42: 59 | C42: H-8b02 | D42: PK-25 | E42: Read model derivato | F42: **Fase 8b.** T-8b05 | G42: Cache rigenerabile, fonte unica (C27) | H42: H-8b01 | I42: Da fare | J42: =IF(I42="Fatto","✔ Sì","✘ No") | K42: SCIBETTA | N42: — | O42: — | R42: Dopo GO | S42: 0 | T42: T-8b05 | U42: H-8b01 | V42: api/
A43: 8b | B43: 60 | C43: H-8b05 | D43: PK-25 | E43: Gate solo da sessione umana | F43: **Fase 8b.** T-8b08 (C23–C24) | G43: La UI non esegue build/test/git | H43: H-8b01, H-403 | I43: Da fare | J43: =IF(I43="Fatto","✔ Sì","✘ No") | K43: SCIBETTA | N43: — | O43: — | R43: Dopo GO | S43: 0 | T43: T-8b08 | U43: H-403, H-8b01 | V43: api/
A44: 8b | B44: 61 | C44: H-8b03 | D44: PK-26 | E44: `ui/` viste | F44: **Fase 8b.** T-8b06 | G44: Portfolio, LIMET, HELIOS, CEREBRO, Criticità | H44: H-8b02 | I44: Da fare | J44: =IF(I44="Fatto","✔ Sì","✘ No") | K44: NARO | N44: — | O44: — | R44: Dopo GO | S44: 0 | T44: T-8b06 | U44: H-8b02 | V44: ui/, [N] shim launcher :8799
A45: 8b | B45: 62 | C45: H-8b04 | D45: PK-26 | E45: Vista Permessi agenti | F45: **Fase 8b.** T-405, T-8b07 | G45: Conferma, motivazione, audit, rollback | H45: H-404, H-8b03 | I45: Da fare | J45: =IF(I45="Fatto","✔ Sì","✘ No") | K45: NARO | N45: — | O45: — | R45: Dopo GO | S45: 0 | T45: T-405, T-8b07 | U45: H-404, H-8b03 | V45: ui/, [N] shim launcher :8799
A46: 8b | B46: 63 | C46: H-8b06 | D46: PK-26 | E46: Grafica e accessibilità | F46: **Fase 8b.** T-8b09 | G46: SVG/Canvas, WCAG 2.1 AA, budget prestazioni (C26) | H46: H-8b03 | I46: Da fare | J46: =IF(I46="Fatto","✔ Sì","✘ No") | K46: NARO | N46: — | O46: — | R46: Dopo GO | S46: 0 | T46: T-8b09 | U46: H-8b03 | V46: ui/, [N] shim launcher :8799
A47: 8b | B47: 64 | C47: H-8b07 | D47: PK-26 | E47: Governance dipendenze npm | F47: **Fase 8b.** T-8b10 | G47: Lockfile, licenze, audit, SBOM (C25) | H47: H-8b03 | I47: Da fare | J47: =IF(I47="Fatto","✔ Sì","✘ No") | K47: NARO | N47: — | O47: — | R47: Dopo GO | S47: 0 | T47: T-8b10 | U47: H-8b03 | V47: ui/, [N] shim launcher :8799
A48: 8b | B48: 65 | C48: H-8b08 | D48: PK-26 | E48: Sostituzione launcher :8799 | F48: **Fase 8b.** T-304 | G48: Tramite shim | H48: H-304, H-8b03 | I48: Da fare | J48: =IF(I48="Fatto","✔ Sì","✘ No") | K48: NARO | N48: — | O48: — | R48: Dopo GO | S48: 0 | T48: T-304 | U48: H-304, H-8b03 | V48: ui/, [N] shim launcher :8799
A49: 9 | B49: 66 | C49: H-901 | D49: PK-27 | E49: Scenari E2E ALA V1–V24 | F49: **Fase 9.** `E2E_VERIFICATION.md` (V1–V24) | G49: Catena completa su 3 OS, progetto pilota | H49: Fasi 5–8 | I49: Da fare | J49: =IF(I49="Fatto","✔ Sì","✘ No") | K49: SCIBETTA | N49: — | O49: — | R49: Dopo GO | S49: 0 | T49: — | U49: — | V49: E2E_VERIFICATION.md
A50: 9 | B50: 67 | C50: H-902 | D50: PK-28 | E50: README e troubleshooting plugin | F50: **Fase 9.** `agents/plugin/README.md` | G50: Installazione, configurazione, errori | H50: H-901 [P] | I50: Da fare | J50: =IF(I50="Fatto","✔ Sì","✘ No") | K50: NARO | N50: — | O50: — | R50: Dopo GO | S50: 0 | T50: — | U50: H-901 | V50: agents/plugin/README.md
A51: 11 | B51: 68 | C51: H-1101 | D51: PK-28 | E51: Manuali, NOTICE, runbook | F51: **Fase 11.** Revisione approvata | G51: Documentazione finale | H51: H-901 | I51: Da fare | J51: =IF(I51="Fatto","✔ Sì","✘ No") | K51: NARO | N51: — | O51: — | R51: Dopo GO | S51: 0 | T51: — | U51: H-901 | V51: agents/plugin/README.md, docs/ (manuali, NOTICE, runbook)
A52: 10 | B52: 69 | C52: H-1001 | D52: PK-29 | E52: Hardening | F52: **Fase 10.** Nessun T-xxx in IN §6 **[N]**: verifica = audit | G52: Log immutabili, sandbox, SBOM, audit | H52: H-901 | I52: Da fare | J52: =IF(I52="Fatto","✔ Sì","✘ No") | K52: SCIBETTA | N52: — | O52: — | R52: Dopo GO | S52: 0 | T52: — | U52: H-901 | V52: [N] log immutabili, sandbox, SBOM
A53: 12 | B53: 70 | C53: H-1201 | D53: PK-30 | E53: Rollout sul pilota | F53: **Fase 12.** Parere legale **[N]** | G53: Metriche, rollback, parere legale | H53: H-1001, H-1101 | I53: Da fare | J53: =IF(I53="Fatto","✔ Sì","✘ No") | K53: NARO | N53: — | O53: — | R53: Dopo GO | S53: 0 | T53: — | U53: H-1001, H-1101 | V53: docs/ (metriche, rollback)

Sheet Pacchetti
A1: HELIOS — Pacchetti di task adiacenti [P: assegnazione da approvare dal SUPERVISORE]
A2: Un pacchetto = task adiacenti (stessa fase/moduli/test) da implementare insieme, step by step. Lo stato si calcola dai fogli Pre-GO / Post-GO. Risorse: NARO e SCIBETTA lavorano in parallelo su percorsi disgiunti. Criterio di bilanciamento: n. task (nessuna stima disponibile, [N]) e continuità sugli stessi file.
A4: Pacchetto | B4: Onda | C4: Nome | D4: Task H-xxx | E4: N. task | F4: Fatti | G4: Stato | H4: Risorsa | I4: Step risorsa | J4: Test T-xxx | K4: Percorsi toccati | L4: Dipende da (pacchetti) | M4: Parallelizzabile con | N4: Punti di contatto / note [N]
A5: PK-00 | B5: Onda 0 | C5: Discovery (ADR, Costituzione, runtime) | D5: H-101, H-102, H-103 | E5: =COUNTIF('Pre-GO'!D5:D25,A5)+COUNTIF('Post-GO'!D5:D53,A5) | F5: =COUNTIFS('Pre-GO'!D5:D25,A5,'Pre-GO'!I5:I25,"Fatto")+COUNTIFS('Post-GO'!D5:D53,A5,'Post-GO'!I5:I53,"Fatto") | G5: =IF(COUNTIFS('Pre-GO'!D5:D25,A5,'Pre-GO'!I5:I25,"Bloccato")+COUNTIFS('Post-GO'!D5:D53,A5,'Post-GO'!I5:I53,"Bloccato")>0,"Bloccato",IF(F5=E5,"Fatto",IF(COUNTIFS('Pre-GO'!D5:D25,A5,'Pre-GO'!I5:I25,"In corso")+COUNTIFS('Post-GO'!D5:D53,A5,'Post-GO'!I5:I53,"In corso")+COUNTIFS('Pre-GO'!D5:D25,A5,'Pre-GO'!I5:I25,"In review")+COUNTIFS('Post-GO'!D5:D53,A5,'Post-GO'!I5:I53,"In review")+F5>0,"In corso","Da fare"))) | H5: SUPERVISORE | I5: Chiuso | J5: — | K5: docs/adr/, docs/CONSTITUTION.md | L5: — | M5: — | N5: Completato 2026-10-29.
A6: PK-01 | B6: Onda 1 | C6: Contratti JSON | D6: H-303 | E6: =COUNTIF('Pre-GO'!D5:D25,A6)+COUNTIF('Post-GO'!D5:D53,A6) | F6: =COUNTIFS('Pre-GO'!D5:D25,A6,'Pre-GO'!I5:I25,"Fatto")+COUNTIFS('Post-GO'!D5:D53,A6,'Post-GO'!I5:I53,"Fatto") | G6: =IF(COUNTIFS('Pre-GO'!D5:D25,A6,'Pre-GO'!I5:I25,"Bloccato")+COUNTIFS('Post-GO'!D5:D53,A6,'Post-GO'!I5:I53,"Bloccato")>0,"Bloccato",IF(F6=E6,"Fatto",IF(COUNTIFS('Pre-GO'!D5:D25,A6,'Pre-GO'!I5:I25,"In corso")+COUNTIFS('Post-GO'!D5:D53,A6,'Post-GO'!I5:I53,"In corso")+COUNTIFS('Pre-GO'!D5:D25,A6,'Pre-GO'!I5:I25,"In review")+COUNTIFS('Post-GO'!D5:D53,A6,'Post-GO'!I5:I53,"In review")+F6>0,"In corso","Da fare"))) | H6: SCIBETTA | I6: S1 | J6: T-303 | K6: agents/contracts/ | L6: PK-00 | M6: PK-02, PK-03, PK-04 | N6: Congela gli schemi prima di Fase 4: modifiche successive solo da SCIBETTA (owner di agents/contracts/).
A7: PK-02 | B7: Onda 1 | C7: Inventario e ledger ECC | D7: H-201, H-202 | E7: =COUNTIF('Pre-GO'!D5:D25,A7)+COUNTIF('Post-GO'!D5:D53,A7) | F7: =COUNTIFS('Pre-GO'!D5:D25,A7,'Pre-GO'!I5:I25,"Fatto")+COUNTIFS('Post-GO'!D5:D53,A7,'Post-GO'!I5:I53,"Fatto") | G7: =IF(COUNTIFS('Pre-GO'!D5:D25,A7,'Pre-GO'!I5:I25,"Bloccato")+COUNTIFS('Post-GO'!D5:D53,A7,'Post-GO'!I5:I53,"Bloccato")>0,"Bloccato",IF(F7=E7,"Fatto",IF(COUNTIFS('Pre-GO'!D5:D25,A7,'Pre-GO'!I5:I25,"In corso")+COUNTIFS('Post-GO'!D5:D53,A7,'Post-GO'!I5:I53,"In corso")+COUNTIFS('Pre-GO'!D5:D25,A7,'Pre-GO'!I5:I25,"In review")+COUNTIFS('Post-GO'!D5:D53,A7,'Post-GO'!I5:I53,"In review")+F7>0,"In corso","Da fare"))) | H7: NARO | I7: N1 | J7: T-201, T-202 | K7: agents/tools/inventory_ecc.py, agents/assets/ecc-ledger.json, NOTICE | L7: PK-00 | M7: PK-01, PK-04 | N7: Owner di agents/assets/ = NARO.
A8: PK-03 | B8: Onda 1 | C8: Revisione asset e matrice catena | D8: H-203, H-204 | E8: =COUNTIF('Pre-GO'!D5:D25,A8)+COUNTIF('Post-GO'!D5:D53,A8) | F8: =COUNTIFS('Pre-GO'!D5:D25,A8,'Pre-GO'!I5:I25,"Fatto")+COUNTIFS('Post-GO'!D5:D53,A8,'Post-GO'!I5:I53,"Fatto") | G8: =IF(COUNTIFS('Pre-GO'!D5:D25,A8,'Pre-GO'!I5:I25,"Bloccato")+COUNTIFS('Post-GO'!D5:D53,A8,'Post-GO'!I5:I53,"Bloccato")>0,"Bloccato",IF(F8=E8,"Fatto",IF(COUNTIFS('Pre-GO'!D5:D25,A8,'Pre-GO'!I5:I25,"In corso")+COUNTIFS('Post-GO'!D5:D53,A8,'Post-GO'!I5:I53,"In corso")+COUNTIFS('Pre-GO'!D5:D25,A8,'Pre-GO'!I5:I25,"In review")+COUNTIFS('Post-GO'!D5:D53,A8,'Post-GO'!I5:I53,"In review")+F8>0,"In corso","Da fare"))) | H8: NARO | I8: N2 | J8: T-204 | K8: docs/ecc-review.md, docs/chain-matrix.md, agents/assets/chain-matrix.json | L8: PK-02 | M8: PK-01, PK-05, PK-06 | N8: Matrice da approvare dal SUPERVISORE.
A9: PK-04 | B9: Onda 1 | C9: Import LIMET/CEREBRO nel monorepo (azione del SUPERVISORE) | D9: H-301 | E9: =COUNTIF('Pre-GO'!D5:D25,A9)+COUNTIF('Post-GO'!D5:D53,A9) | F9: =COUNTIFS('Pre-GO'!D5:D25,A9,'Pre-GO'!I5:I25,"Fatto")+COUNTIFS('Post-GO'!D5:D53,A9,'Post-GO'!I5:I53,"Fatto") | G9: =IF(COUNTIFS('Pre-GO'!D5:D25,A9,'Pre-GO'!I5:I25,"Bloccato")+COUNTIFS('Post-GO'!D5:D53,A9,'Post-GO'!I5:I53,"Bloccato")>0,"Bloccato",IF(F9=E9,"Fatto",IF(COUNTIFS('Pre-GO'!D5:D25,A9,'Pre-GO'!I5:I25,"In corso")+COUNTIFS('Post-GO'!D5:D53,A9,'Post-GO'!I5:I53,"In corso")+COUNTIFS('Pre-GO'!D5:D25,A9,'Pre-GO'!I5:I25,"In review")+COUNTIFS('Post-GO'!D5:D53,A9,'Post-GO'!I5:I53,"In review")+F9>0,"In corso","Da fare"))) | H9: SUPERVISORE | I9: Commit/push del SUPERVISORE | J9: — | K9: limet/, cerebro/ (nuove cartelle di import) | L9: PK-00 | M9: PK-01, PK-02, PK-03 | N9: [N] Q-9 (remote/storia CEREBRO). Sblocca PK-05b, PK-06, PK-07. Nessun agente esegue commit/push.
A10: PK-05 | B10: Onda 1 | C10: CI a matrice (3 OS) | D10: H-306 | E10: =COUNTIF('Pre-GO'!D5:D25,A10)+COUNTIF('Post-GO'!D5:D53,A10) | F10: =COUNTIFS('Pre-GO'!D5:D25,A10,'Pre-GO'!I5:I25,"Fatto")+COUNTIFS('Post-GO'!D5:D53,A10,'Post-GO'!I5:I53,"Fatto") | G10: =IF(COUNTIFS('Pre-GO'!D5:D25,A10,'Pre-GO'!I5:I25,"Bloccato")+COUNTIFS('Post-GO'!D5:D53,A10,'Post-GO'!I5:I53,"Bloccato")>0,"Bloccato",IF(F10=E10,"Fatto",IF(COUNTIFS('Pre-GO'!D5:D25,A10,'Pre-GO'!I5:I25,"In corso")+COUNTIFS('Post-GO'!D5:D53,A10,'Post-GO'!I5:I53,"In corso")+COUNTIFS('Pre-GO'!D5:D25,A10,'Pre-GO'!I5:I25,"In review")+COUNTIFS('Post-GO'!D5:D53,A10,'Post-GO'!I5:I53,"In review")+F10>0,"In corso","Da fare"))) | H10: SCIBETTA | I10: S2 | J10: T-306 | K10: .github/workflows/ci.yml | L10: PK-00 (H-103) — avviabile subito | M10: PK-02, PK-03 | N10: Dipende solo da H-103 (TASK_LIST). Va chiuso prima di PK-05b: entrambi toccano ci.yml, stessa persona.
A11: PK-05b | B11: Onda 1 (dopo H-301) | C11: Segreti fuori dal repo | D11: H-302 | E11: =COUNTIF('Pre-GO'!D5:D25,A11)+COUNTIF('Post-GO'!D5:D53,A11) | F11: =COUNTIFS('Pre-GO'!D5:D25,A11,'Pre-GO'!I5:I25,"Fatto")+COUNTIFS('Post-GO'!D5:D53,A11,'Post-GO'!I5:I53,"Fatto") | G11: =IF(COUNTIFS('Pre-GO'!D5:D25,A11,'Pre-GO'!I5:I25,"Bloccato")+COUNTIFS('Post-GO'!D5:D53,A11,'Post-GO'!I5:I53,"Bloccato")>0,"Bloccato",IF(F11=E11,"Fatto",IF(COUNTIFS('Pre-GO'!D5:D25,A11,'Pre-GO'!I5:I25,"In corso")+COUNTIFS('Post-GO'!D5:D53,A11,'Post-GO'!I5:I53,"In corso")+COUNTIFS('Pre-GO'!D5:D25,A11,'Pre-GO'!I5:I25,"In review")+COUNTIFS('Post-GO'!D5:D53,A11,'Post-GO'!I5:I53,"In review")+F11>0,"In corso","Da fare"))) | H11: SCIBETTA | I11: S2b | J11: T-302 | K11: .gitignore, projects.example.json, .github/workflows/ci.yml (scansione segreti) | L11: PK-04 (H-301), PK-05 | M11: PK-03, PK-06, PK-07 | N11: Dipende da H-301. Tocca ci.yml dopo PK-05 (stessa persona). [N] percorso dello script di scansione segreti.
A12: PK-06 | B12: Onda 1 (dopo H-301) | C12: Shim compat e test confini | D12: H-304, H-305 | E12: =COUNTIF('Pre-GO'!D5:D25,A12)+COUNTIF('Post-GO'!D5:D53,A12) | F12: =COUNTIFS('Pre-GO'!D5:D25,A12,'Pre-GO'!I5:I25,"Fatto")+COUNTIFS('Post-GO'!D5:D53,A12,'Post-GO'!I5:I53,"Fatto") | G12: =IF(COUNTIFS('Pre-GO'!D5:D25,A12,'Pre-GO'!I5:I25,"Bloccato")+COUNTIFS('Post-GO'!D5:D53,A12,'Post-GO'!I5:I53,"Bloccato")>0,"Bloccato",IF(F12=E12,"Fatto",IF(COUNTIFS('Pre-GO'!D5:D25,A12,'Pre-GO'!I5:I25,"In corso")+COUNTIFS('Post-GO'!D5:D53,A12,'Post-GO'!I5:I53,"In corso")+COUNTIFS('Pre-GO'!D5:D25,A12,'Pre-GO'!I5:I25,"In review")+COUNTIFS('Post-GO'!D5:D53,A12,'Post-GO'!I5:I53,"In review")+F12>0,"In corso","Da fare"))) | H12: SCIBETTA | I12: S3 | J12: T-304, T-305 | K12: compat/, tests/test_module_boundaries.py | L12: PK-04 (H-301) | M12: PK-03, PK-07 | N12: Dipendono da H-301. Parità su Windows e Unix (C13).
A13: PK-07 | B13: Onda 1 (dopo H-301) | C13: Correzione percorso CEREBRO in CLAUDE.md | D13: H-307 | E13: =COUNTIF('Pre-GO'!D5:D25,A13)+COUNTIF('Post-GO'!D5:D53,A13) | F13: =COUNTIFS('Pre-GO'!D5:D25,A13,'Pre-GO'!I5:I25,"Fatto")+COUNTIFS('Post-GO'!D5:D53,A13,'Post-GO'!I5:I53,"Fatto") | G13: =IF(COUNTIFS('Pre-GO'!D5:D25,A13,'Pre-GO'!I5:I25,"Bloccato")+COUNTIFS('Post-GO'!D5:D53,A13,'Post-GO'!I5:I53,"Bloccato")>0,"Bloccato",IF(F13=E13,"Fatto",IF(COUNTIFS('Pre-GO'!D5:D25,A13,'Pre-GO'!I5:I25,"In corso")+COUNTIFS('Post-GO'!D5:D53,A13,'Post-GO'!I5:I53,"In corso")+COUNTIFS('Pre-GO'!D5:D25,A13,'Pre-GO'!I5:I25,"In review")+COUNTIFS('Post-GO'!D5:D53,A13,'Post-GO'!I5:I53,"In review")+F13>0,"In corso","Da fare"))) | H13: NARO | I13: N3 | J13: — | K13: cerebro/CLAUDE.md [P: copia interna] | L13: PK-04 | M13: PK-05, PK-06 | N13: [N] percorso esatto del file nella copia importata.
A14: PK-08 | B14: Onda 2 | C14: Runner con allowlist e policy permessi | D14: H-401, H-404 | E14: =COUNTIF('Pre-GO'!D5:D25,A14)+COUNTIF('Post-GO'!D5:D53,A14) | F14: =COUNTIFS('Pre-GO'!D5:D25,A14,'Pre-GO'!I5:I25,"Fatto")+COUNTIFS('Post-GO'!D5:D53,A14,'Post-GO'!I5:I53,"Fatto") | G14: =IF(COUNTIFS('Pre-GO'!D5:D25,A14,'Pre-GO'!I5:I25,"Bloccato")+COUNTIFS('Post-GO'!D5:D53,A14,'Post-GO'!I5:I53,"Bloccato")>0,"Bloccato",IF(F14=E14,"Fatto",IF(COUNTIFS('Pre-GO'!D5:D25,A14,'Pre-GO'!I5:I25,"In corso")+COUNTIFS('Post-GO'!D5:D53,A14,'Post-GO'!I5:I53,"In corso")+COUNTIFS('Pre-GO'!D5:D25,A14,'Pre-GO'!I5:I25,"In review")+COUNTIFS('Post-GO'!D5:D53,A14,'Post-GO'!I5:I53,"In review")+F14>0,"In corso","Da fare"))) | H14: SCIBETTA | I14: S4 | J14: T-401, T-402, T-405 | K14: agents/runner/, agents/policy/policy.json, agents/policy/floor.json | L14: PK-01, PK-05, PK-05b, PK-06, PK-07 (Fase 3 chiusa) | M14: PK-10, PK-11 | N14: Output del runner = contratto di PK-01 (sola lettura per NARO).
A15: PK-09 | B15: Onda 2 | C15: Ruoli PoC (analyst, developer, reviewer) | D15: H-402 | E15: =COUNTIF('Pre-GO'!D5:D25,A15)+COUNTIF('Post-GO'!D5:D53,A15) | F15: =COUNTIFS('Pre-GO'!D5:D25,A15,'Pre-GO'!I5:I25,"Fatto")+COUNTIFS('Post-GO'!D5:D53,A15,'Post-GO'!I5:I53,"Fatto") | G15: =IF(COUNTIFS('Pre-GO'!D5:D25,A15,'Pre-GO'!I5:I25,"Bloccato")+COUNTIFS('Post-GO'!D5:D53,A15,'Post-GO'!I5:I53,"Bloccato")>0,"Bloccato",IF(F15=E15,"Fatto",IF(COUNTIFS('Pre-GO'!D5:D25,A15,'Pre-GO'!I5:I25,"In corso")+COUNTIFS('Post-GO'!D5:D53,A15,'Post-GO'!I5:I53,"In corso")+COUNTIFS('Pre-GO'!D5:D25,A15,'Pre-GO'!I5:I25,"In review")+COUNTIFS('Post-GO'!D5:D53,A15,'Post-GO'!I5:I53,"In review")+F15>0,"In corso","Da fare"))) | H15: SCIBETTA | I15: S5 | J15: T-403 | K15: agents/roles/*.md | L15: PK-08 (H-404), PK-01 | M15: PK-10, PK-11 | N15: Nessun Bash libero nei tools.
A16: PK-10 | B16: Onda 2 | C16: Gate umano meccanico sul PLAN | D16: H-403 | E16: =COUNTIF('Pre-GO'!D5:D25,A16)+COUNTIF('Post-GO'!D5:D53,A16) | F16: =COUNTIFS('Pre-GO'!D5:D25,A16,'Pre-GO'!I5:I25,"Fatto")+COUNTIFS('Post-GO'!D5:D53,A16,'Post-GO'!I5:I53,"Fatto") | G16: =IF(COUNTIFS('Pre-GO'!D5:D25,A16,'Pre-GO'!I5:I25,"Bloccato")+COUNTIFS('Post-GO'!D5:D53,A16,'Post-GO'!I5:I53,"Bloccato")>0,"Bloccato",IF(F16=E16,"Fatto",IF(COUNTIFS('Pre-GO'!D5:D25,A16,'Pre-GO'!I5:I25,"In corso")+COUNTIFS('Post-GO'!D5:D53,A16,'Post-GO'!I5:I53,"In corso")+COUNTIFS('Pre-GO'!D5:D25,A16,'Pre-GO'!I5:I25,"In review")+COUNTIFS('Post-GO'!D5:D53,A16,'Post-GO'!I5:I53,"In review")+F16>0,"In corso","Da fare"))) | H16: NARO | I16: N4 | J16: T-404 | K16: agents/workflow/gate.py | L16: PK-01 | M16: PK-08, PK-09, PK-11 | N16: Approvazione solo da sessione umana (C24).
A17: PK-11 | B17: Onda 2 | C17: Prova del plugin Claude Code (V13/V14) | D17: H-407 | E17: =COUNTIF('Pre-GO'!D5:D25,A17)+COUNTIF('Post-GO'!D5:D53,A17) | F17: =COUNTIFS('Pre-GO'!D5:D25,A17,'Pre-GO'!I5:I25,"Fatto")+COUNTIFS('Post-GO'!D5:D53,A17,'Post-GO'!I5:I53,"Fatto") | G17: =IF(COUNTIFS('Pre-GO'!D5:D25,A17,'Pre-GO'!I5:I25,"Bloccato")+COUNTIFS('Post-GO'!D5:D53,A17,'Post-GO'!I5:I53,"Bloccato")>0,"Bloccato",IF(F17=E17,"Fatto",IF(COUNTIFS('Pre-GO'!D5:D25,A17,'Pre-GO'!I5:I25,"In corso")+COUNTIFS('Post-GO'!D5:D53,A17,'Post-GO'!I5:I53,"In corso")+COUNTIFS('Pre-GO'!D5:D25,A17,'Pre-GO'!I5:I25,"In review")+COUNTIFS('Post-GO'!D5:D53,A17,'Post-GO'!I5:I53,"In review")+F17>0,"In corso","Da fare"))) | H17: NARO | I17: N5 | J17: T-407 | K17: agents/plugin/ | L17: PK-01 | M17: PK-08, PK-09, PK-10 | N17: [N] sintassi Dynamic Workflow in Claude Code 2.1.311; se non riconosciuto: piano B in poc-report.md.
A18: PK-12 | B18: Onda 2 | C18: Asset ECC portato + A/B | D18: H-405 | E18: =COUNTIF('Pre-GO'!D5:D25,A18)+COUNTIF('Post-GO'!D5:D53,A18) | F18: =COUNTIFS('Pre-GO'!D5:D25,A18,'Pre-GO'!I5:I25,"Fatto")+COUNTIFS('Post-GO'!D5:D53,A18,'Post-GO'!I5:I53,"Fatto") | G18: =IF(COUNTIFS('Pre-GO'!D5:D25,A18,'Pre-GO'!I5:I25,"Bloccato")+COUNTIFS('Post-GO'!D5:D53,A18,'Post-GO'!I5:I53,"Bloccato")>0,"Bloccato",IF(F18=E18,"Fatto",IF(COUNTIFS('Pre-GO'!D5:D25,A18,'Pre-GO'!I5:I25,"In corso")+COUNTIFS('Post-GO'!D5:D53,A18,'Post-GO'!I5:I53,"In corso")+COUNTIFS('Pre-GO'!D5:D25,A18,'Pre-GO'!I5:I25,"In review")+COUNTIFS('Post-GO'!D5:D53,A18,'Post-GO'!I5:I53,"In review")+F18>0,"In corso","Da fare"))) | H18: SCIBETTA | I18: S6 | J18: T-406 | K18: tests/test_ab_metrics.py, [N] cartella dell'asset ecc-code-reviewer | L18: PK-08, PK-09 | M18: PK-11 | N18: D1–D10 approvati (Q-6); pilota in test\ (Q-5).
A19: PK-13 | B19: Onda 2 | C19: Rapporto go/no-go (compila NARO, decide il SUPERVISORE) | D19: H-406 | E19: =COUNTIF('Pre-GO'!D5:D25,A19)+COUNTIF('Post-GO'!D5:D53,A19) | F19: =COUNTIFS('Pre-GO'!D5:D25,A19,'Pre-GO'!I5:I25,"Fatto")+COUNTIFS('Post-GO'!D5:D53,A19,'Post-GO'!I5:I53,"Fatto") | G19: =IF(COUNTIFS('Pre-GO'!D5:D25,A19,'Pre-GO'!I5:I25,"Bloccato")+COUNTIFS('Post-GO'!D5:D53,A19,'Post-GO'!I5:I53,"Bloccato")>0,"Bloccato",IF(F19=E19,"Fatto",IF(COUNTIFS('Pre-GO'!D5:D25,A19,'Pre-GO'!I5:I25,"In corso")+COUNTIFS('Post-GO'!D5:D53,A19,'Post-GO'!I5:I53,"In corso")+COUNTIFS('Pre-GO'!D5:D25,A19,'Pre-GO'!I5:I25,"In review")+COUNTIFS('Post-GO'!D5:D53,A19,'Post-GO'!I5:I53,"In review")+F19>0,"In corso","Da fare"))) | H19: NARO | I19: N6 | J19: — | K19: docs/poc-report.md | L19: PK-08…PK-12 | M19: — | N19: PUNTO DI DECISIONE: GO / NO-GO / piano B. Le Onde 3+ partono solo dopo GO.
A20: PK-14 | B20: Onda 3 (dopo GO) | C20: Contratti della catena e skill runner | D20: H-308, H-409 | E20: =COUNTIF('Pre-GO'!D5:D25,A20)+COUNTIF('Post-GO'!D5:D53,A20) | F20: =COUNTIFS('Pre-GO'!D5:D25,A20,'Pre-GO'!I5:I25,"Fatto")+COUNTIFS('Post-GO'!D5:D53,A20,'Post-GO'!I5:I53,"Fatto") | G20: =IF(COUNTIFS('Pre-GO'!D5:D25,A20,'Pre-GO'!I5:I25,"Bloccato")+COUNTIFS('Post-GO'!D5:D53,A20,'Post-GO'!I5:I53,"Bloccato")>0,"Bloccato",IF(F20=E20,"Fatto",IF(COUNTIFS('Pre-GO'!D5:D25,A20,'Pre-GO'!I5:I25,"In corso")+COUNTIFS('Post-GO'!D5:D53,A20,'Post-GO'!I5:I53,"In corso")+COUNTIFS('Pre-GO'!D5:D25,A20,'Pre-GO'!I5:I25,"In review")+COUNTIFS('Post-GO'!D5:D53,A20,'Post-GO'!I5:I53,"In review")+F20>0,"In corso","Da fare"))) | H20: SCIBETTA | I20: S7 | J20: T-308, T-409 | K20: agents/contracts/ (nuovi schemi), agents/plugin/skills/limet-runner/ | L20: GO; PK-08 | M20: PK-15 | N20: Sblocca PK-16 e i ruoli (sync point).
A21: PK-15 | B21: Onda 3 (dopo GO) | C21: Scheduler e regole comuni dei ruoli | D21: H-408, H-611 | E21: =COUNTIF('Pre-GO'!D5:D25,A21)+COUNTIF('Post-GO'!D5:D53,A21) | F21: =COUNTIFS('Pre-GO'!D5:D25,A21,'Pre-GO'!I5:I25,"Fatto")+COUNTIFS('Post-GO'!D5:D53,A21,'Post-GO'!I5:I53,"Fatto") | G21: =IF(COUNTIFS('Pre-GO'!D5:D25,A21,'Pre-GO'!I5:I25,"Bloccato")+COUNTIFS('Post-GO'!D5:D53,A21,'Post-GO'!I5:I53,"Bloccato")>0,"Bloccato",IF(F21=E21,"Fatto",IF(COUNTIFS('Pre-GO'!D5:D25,A21,'Pre-GO'!I5:I25,"In corso")+COUNTIFS('Post-GO'!D5:D53,A21,'Post-GO'!I5:I53,"In corso")+COUNTIFS('Pre-GO'!D5:D25,A21,'Pre-GO'!I5:I25,"In review")+COUNTIFS('Post-GO'!D5:D53,A21,'Post-GO'!I5:I53,"In review")+F21>0,"In corso","Da fare"))) | H21: NARO | I21: N7 | J21: T-408, T-610 | K21: agents/plugin/scheduler/, agents/plugin/agents/_common.md | L21: GO; PK-08 | M21: PK-14 | N21: _common.md: owner NARO, sola lettura per SCIBETTA.
A22: PK-16 | B22: Onda 4 (dopo GO) | C22: Porting asset ECC | D22: H-501, H-502, H-503 | E22: =COUNTIF('Pre-GO'!D5:D25,A22)+COUNTIF('Post-GO'!D5:D53,A22) | F22: =COUNTIFS('Pre-GO'!D5:D25,A22,'Pre-GO'!I5:I25,"Fatto")+COUNTIFS('Post-GO'!D5:D53,A22,'Post-GO'!I5:I53,"Fatto") | G22: =IF(COUNTIFS('Pre-GO'!D5:D25,A22,'Pre-GO'!I5:I25,"Bloccato")+COUNTIFS('Post-GO'!D5:D53,A22,'Post-GO'!I5:I53,"Bloccato")>0,"Bloccato",IF(F22=E22,"Fatto",IF(COUNTIFS('Pre-GO'!D5:D25,A22,'Pre-GO'!I5:I25,"In corso")+COUNTIFS('Post-GO'!D5:D53,A22,'Post-GO'!I5:I53,"In corso")+COUNTIFS('Pre-GO'!D5:D25,A22,'Pre-GO'!I5:I25,"In review")+COUNTIFS('Post-GO'!D5:D53,A22,'Post-GO'!I5:I53,"In review")+F22>0,"In corso","Da fare"))) | H22: NARO | I22: N8 | J22: T-501, T-502, T-503 | K22: agents/assets/ (ecc-*), test di agnosticità | L22: PK-03, PK-14 | M22: PK-17 | N22: Aspetta H-308 (PK-14).
A23: PK-17 | B23: Onda 4 (dopo GO) | C23: Ruoli di sviluppo | D23: H-602, H-603, H-604, H-605 | E23: =COUNTIF('Pre-GO'!D5:D25,A23)+COUNTIF('Post-GO'!D5:D53,A23) | F23: =COUNTIFS('Pre-GO'!D5:D25,A23,'Pre-GO'!I5:I25,"Fatto")+COUNTIFS('Post-GO'!D5:D53,A23,'Post-GO'!I5:I53,"Fatto") | G23: =IF(COUNTIFS('Pre-GO'!D5:D25,A23,'Pre-GO'!I5:I25,"Bloccato")+COUNTIFS('Post-GO'!D5:D53,A23,'Post-GO'!I5:I53,"Bloccato")>0,"Bloccato",IF(F23=E23,"Fatto",IF(COUNTIFS('Pre-GO'!D5:D25,A23,'Pre-GO'!I5:I25,"In corso")+COUNTIFS('Post-GO'!D5:D53,A23,'Post-GO'!I5:I53,"In corso")+COUNTIFS('Pre-GO'!D5:D25,A23,'Pre-GO'!I5:I25,"In review")+COUNTIFS('Post-GO'!D5:D53,A23,'Post-GO'!I5:I53,"In review")+F23>0,"In corso","Da fare"))) | H23: SCIBETTA | I23: S8 | J23: T-601, T-602, T-603, T-604 | K23: agents/plugin/agents/{analyst,developer,tester,integrator}.md | L23: PK-14, PK-15, PK-09 | M23: PK-16, PK-18 | N23: Stessa cartella di PK-18 ma file distinti.
A24: PK-18 | B24: Onda 4 (dopo GO) | C24: Ruoli di controllo | D24: H-606, H-607, H-608, H-609, H-610, H-601 | E24: =COUNTIF('Pre-GO'!D5:D25,A24)+COUNTIF('Post-GO'!D5:D53,A24) | F24: =COUNTIFS('Pre-GO'!D5:D25,A24,'Pre-GO'!I5:I25,"Fatto")+COUNTIFS('Post-GO'!D5:D53,A24,'Post-GO'!I5:I53,"Fatto") | G24: =IF(COUNTIFS('Pre-GO'!D5:D25,A24,'Pre-GO'!I5:I25,"Bloccato")+COUNTIFS('Post-GO'!D5:D53,A24,'Post-GO'!I5:I53,"Bloccato")>0,"Bloccato",IF(F24=E24,"Fatto",IF(COUNTIFS('Pre-GO'!D5:D25,A24,'Pre-GO'!I5:I25,"In corso")+COUNTIFS('Post-GO'!D5:D53,A24,'Post-GO'!I5:I53,"In corso")+COUNTIFS('Pre-GO'!D5:D25,A24,'Pre-GO'!I5:I25,"In review")+COUNTIFS('Post-GO'!D5:D53,A24,'Post-GO'!I5:I53,"In review")+F24>0,"In corso","Da fare"))) | H24: NARO | I24: N9 | J24: T-605, T-606, T-607, T-608, T-609, T-403 | K24: agents/plugin/agents/{test-reader,reviewer,validator,metrics-observer,e2e-designer,e2e-reader}.md, agents/metrics/ | L24: PK-14, PK-15, PK-09 | M24: PK-17 | N24: Stessa cartella di PK-17 ma file distinti.
A25: PK-19 | B25: Onda 5 (dopo GO) | C25: Workflow core e permessi tool | D25: H-701, H-703, H-704, H-705, H-707, H-708, H-710 | E25: =COUNTIF('Pre-GO'!D5:D25,A25)+COUNTIF('Post-GO'!D5:D53,A25) | F25: =COUNTIFS('Pre-GO'!D5:D25,A25,'Pre-GO'!I5:I25,"Fatto")+COUNTIFS('Post-GO'!D5:D53,A25,'Post-GO'!I5:I53,"Fatto") | G25: =IF(COUNTIFS('Pre-GO'!D5:D25,A25,'Pre-GO'!I5:I25,"Bloccato")+COUNTIFS('Post-GO'!D5:D53,A25,'Post-GO'!I5:I53,"Bloccato")>0,"Bloccato",IF(F25=E25,"Fatto",IF(COUNTIFS('Pre-GO'!D5:D25,A25,'Pre-GO'!I5:I25,"In corso")+COUNTIFS('Post-GO'!D5:D53,A25,'Post-GO'!I5:I53,"In corso")+COUNTIFS('Pre-GO'!D5:D25,A25,'Pre-GO'!I5:I25,"In review")+COUNTIFS('Post-GO'!D5:D53,A25,'Post-GO'!I5:I53,"In review")+F25>0,"In corso","Da fare"))) | H25: SCIBETTA | I25: S9 | J25: T-701, T-703, T-704, T-705, T-707, T-708, T-710 | K25: agents/plugin/ (limet-change.js, [N] file per onde/gate), agents/policy/ | L25: PK-14…PK-18, H-407 | M25: PK-20, PK-22 | N25: [N] se limet-change.js è un file unico va scritto da una sola persona (SCIBETTA).
A26: PK-20 | B26: Onda 5 (dopo GO) | C26: Stato/eventi, report e gate di merge | D26: H-706, H-709, H-711 | E26: =COUNTIF('Pre-GO'!D5:D25,A26)+COUNTIF('Post-GO'!D5:D53,A26) | F26: =COUNTIFS('Pre-GO'!D5:D25,A26,'Pre-GO'!I5:I25,"Fatto")+COUNTIFS('Post-GO'!D5:D53,A26,'Post-GO'!I5:I53,"Fatto") | G26: =IF(COUNTIFS('Pre-GO'!D5:D25,A26,'Pre-GO'!I5:I25,"Bloccato")+COUNTIFS('Post-GO'!D5:D53,A26,'Post-GO'!I5:I53,"Bloccato")>0,"Bloccato",IF(F26=E26,"Fatto",IF(COUNTIFS('Pre-GO'!D5:D25,A26,'Pre-GO'!I5:I25,"In corso")+COUNTIFS('Post-GO'!D5:D53,A26,'Post-GO'!I5:I53,"In corso")+COUNTIFS('Pre-GO'!D5:D25,A26,'Pre-GO'!I5:I25,"In review")+COUNTIFS('Post-GO'!D5:D53,A26,'Post-GO'!I5:I53,"In review")+F26>0,"In corso","Da fare"))) | H26: NARO | I26: N10 | J26: T-706, T-709, T-711 | K26: [N] file di stato, report e gate di merge (da fissare in H-308/H-701) | L26: PK-14…PK-18, H-407 | M26: PK-19 | N26: Contatto: contratto state.json / events.jsonl di H-308. NARO non modifica limet-change.js.
A27: PK-21 | B27: Onda 6 (dopo GO) | C27: Valutazione rischi di prodotto (C28) | D27: H-612 | E27: =COUNTIF('Pre-GO'!D5:D25,A27)+COUNTIF('Post-GO'!D5:D53,A27) | F27: =COUNTIFS('Pre-GO'!D5:D25,A27,'Pre-GO'!I5:I25,"Fatto")+COUNTIFS('Post-GO'!D5:D53,A27,'Post-GO'!I5:I53,"Fatto") | G27: =IF(COUNTIFS('Pre-GO'!D5:D25,A27,'Pre-GO'!I5:I25,"Bloccato")+COUNTIFS('Post-GO'!D5:D53,A27,'Post-GO'!I5:I53,"Bloccato")>0,"Bloccato",IF(F27=E27,"Fatto",IF(COUNTIFS('Pre-GO'!D5:D25,A27,'Pre-GO'!I5:I25,"In corso")+COUNTIFS('Post-GO'!D5:D53,A27,'Post-GO'!I5:I53,"In corso")+COUNTIFS('Pre-GO'!D5:D25,A27,'Pre-GO'!I5:I25,"In review")+COUNTIFS('Post-GO'!D5:D53,A27,'Post-GO'!I5:I53,"In review")+F27>0,"In corso","Da fare"))) | H27: NARO | I27: N11 | J27: T-611 | K27: agents/plugin/agents/risk-assessor.md, RISK-<task>.json | L27: PK-19 (H-701), PK-20 (H-706), H-308 | M27: PK-23, PK-24, PK-25 | N27: risk-assessor ≠ developer, sola lettura.
A28: PK-22 | B28: Onda 5 (dopo GO) | C28: Installer e modifiche documentali a LIMET | D28: H-702, H-712 | E28: =COUNTIF('Pre-GO'!D5:D25,A28)+COUNTIF('Post-GO'!D5:D53,A28) | F28: =COUNTIFS('Pre-GO'!D5:D25,A28,'Pre-GO'!I5:I25,"Fatto")+COUNTIFS('Post-GO'!D5:D53,A28,'Post-GO'!I5:I53,"Fatto") | G28: =IF(COUNTIFS('Pre-GO'!D5:D25,A28,'Pre-GO'!I5:I25,"Bloccato")+COUNTIFS('Post-GO'!D5:D53,A28,'Post-GO'!I5:I53,"Bloccato")>0,"Bloccato",IF(F28=E28,"Fatto",IF(COUNTIFS('Pre-GO'!D5:D25,A28,'Pre-GO'!I5:I25,"In corso")+COUNTIFS('Post-GO'!D5:D53,A28,'Post-GO'!I5:I53,"In corso")+COUNTIFS('Pre-GO'!D5:D25,A28,'Pre-GO'!I5:I25,"In review")+COUNTIFS('Post-GO'!D5:D53,A28,'Post-GO'!I5:I53,"In review")+F28>0,"In corso","Da fare"))) | H28: NARO | I28: N12 | J28: T-702, T-712 | K28: scripts/limet-agents.ps1/.sh, limet/ (documentazione) [P] | L28: H-407; H-712 dopo H-407 (ALA §7) | M28: PK-19 | N28: Ciclo LIMET IT/EN; re-index a cura del SUPERVISORE.
A29: PK-23 | B29: Onda 3+ (dopo GO) | C29: Hook ECC e registro chiamate LLM | D29: H-800, H-800b, H-801, H-802 | E29: =COUNTIF('Pre-GO'!D5:D25,A29)+COUNTIF('Post-GO'!D5:D53,A29) | F29: =COUNTIFS('Pre-GO'!D5:D25,A29,'Pre-GO'!I5:I25,"Fatto")+COUNTIFS('Post-GO'!D5:D53,A29,'Post-GO'!I5:I53,"Fatto") | G29: =IF(COUNTIFS('Pre-GO'!D5:D25,A29,'Pre-GO'!I5:I25,"Bloccato")+COUNTIFS('Post-GO'!D5:D53,A29,'Post-GO'!I5:I53,"Bloccato")>0,"Bloccato",IF(F29=E29,"Fatto",IF(COUNTIFS('Pre-GO'!D5:D25,A29,'Pre-GO'!I5:I25,"In corso")+COUNTIFS('Post-GO'!D5:D53,A29,'Post-GO'!I5:I53,"In corso")+COUNTIFS('Pre-GO'!D5:D25,A29,'Pre-GO'!I5:I25,"In review")+COUNTIFS('Post-GO'!D5:D53,A29,'Post-GO'!I5:I53,"In review")+F29>0,"In corso","Da fare"))) | H29: SCIBETTA | I29: S10 | J29: T-801, T-802 | K29: docs/ecc-hooks-analysis.md, agents/policy/llm-registry.json, [N] wrapper AgentShield | L29: GO; PK-08 | M29: PK-14…PK-22 | N29: H-800 anticipabile in Fase 2 (IN §5). [N] Q-10 licenze AgentShield.
A30: PK-24 | B30: Onda 6 (dopo GO) | C30: Knowledge base HLS_* e accesso agenti | D30: H-803, H-804 | E30: =COUNTIF('Pre-GO'!D5:D25,A30)+COUNTIF('Post-GO'!D5:D53,A30) | F30: =COUNTIFS('Pre-GO'!D5:D25,A30,'Pre-GO'!I5:I25,"Fatto")+COUNTIFS('Post-GO'!D5:D53,A30,'Post-GO'!I5:I53,"Fatto") | G30: =IF(COUNTIFS('Pre-GO'!D5:D25,A30,'Pre-GO'!I5:I25,"Bloccato")+COUNTIFS('Post-GO'!D5:D53,A30,'Post-GO'!I5:I53,"Bloccato")>0,"Bloccato",IF(F30=E30,"Fatto",IF(COUNTIFS('Pre-GO'!D5:D25,A30,'Pre-GO'!I5:I25,"In corso")+COUNTIFS('Post-GO'!D5:D53,A30,'Post-GO'!I5:I53,"In corso")+COUNTIFS('Pre-GO'!D5:D25,A30,'Pre-GO'!I5:I25,"In review")+COUNTIFS('Post-GO'!D5:D53,A30,'Post-GO'!I5:I53,"In review")+F30>0,"In corso","Da fare"))) | H30: SCIBETTA | I30: S11 | J30: T-803, T-804 | K30: [N] script KB / MCP in sola lettura | L30: PK-03, PK-15 | M30: PK-21 | N30: HLS_* creata solo con autorizzazione esplicita (Q9); mai su collection esistenti.
A31: PK-25 | B31: Onda 3+ (dopo GO) | C31: API loopback e read model | D31: H-8b01, H-8b02, H-8b05 | E31: =COUNTIF('Pre-GO'!D5:D25,A31)+COUNTIF('Post-GO'!D5:D53,A31) | F31: =COUNTIFS('Pre-GO'!D5:D25,A31,'Pre-GO'!I5:I25,"Fatto")+COUNTIFS('Post-GO'!D5:D53,A31,'Post-GO'!I5:I53,"Fatto") | G31: =IF(COUNTIFS('Pre-GO'!D5:D25,A31,'Pre-GO'!I5:I25,"Bloccato")+COUNTIFS('Post-GO'!D5:D53,A31,'Post-GO'!I5:I53,"Bloccato")>0,"Bloccato",IF(F31=E31,"Fatto",IF(COUNTIFS('Pre-GO'!D5:D25,A31,'Pre-GO'!I5:I25,"In corso")+COUNTIFS('Post-GO'!D5:D53,A31,'Post-GO'!I5:I53,"In corso")+COUNTIFS('Pre-GO'!D5:D25,A31,'Pre-GO'!I5:I25,"In review")+COUNTIFS('Post-GO'!D5:D53,A31,'Post-GO'!I5:I53,"In review")+F31>0,"In corso","Da fare"))) | H31: SCIBETTA | I31: S12 | J31: T-8b01, T-8b04, T-8b05, T-8b08 | K31: api/ | L31: GO; PK-06, PK-08 | M31: PK-26 (dopo contratto API) | N31: Contatto: contratto API/OpenAPI di H-8b01 da congelare prima di PK-26.
A32: PK-26 | B32: Onda 4+ (dopo GO) | C32: UI (viste, permessi, grafica, npm) e sostituzione launcher | D32: H-8b03, H-8b04, H-8b06, H-8b07, H-8b08 | E32: =COUNTIF('Pre-GO'!D5:D25,A32)+COUNTIF('Post-GO'!D5:D53,A32) | F32: =COUNTIFS('Pre-GO'!D5:D25,A32,'Pre-GO'!I5:I25,"Fatto")+COUNTIFS('Post-GO'!D5:D53,A32,'Post-GO'!I5:I53,"Fatto") | G32: =IF(COUNTIFS('Pre-GO'!D5:D25,A32,'Pre-GO'!I5:I25,"Bloccato")+COUNTIFS('Post-GO'!D5:D53,A32,'Post-GO'!I5:I53,"Bloccato")>0,"Bloccato",IF(F32=E32,"Fatto",IF(COUNTIFS('Pre-GO'!D5:D25,A32,'Pre-GO'!I5:I25,"In corso")+COUNTIFS('Post-GO'!D5:D53,A32,'Post-GO'!I5:I53,"In corso")+COUNTIFS('Pre-GO'!D5:D25,A32,'Pre-GO'!I5:I25,"In review")+COUNTIFS('Post-GO'!D5:D53,A32,'Post-GO'!I5:I53,"In review")+F32>0,"In corso","Da fare"))) | H32: NARO | I32: N13 | J32: T-8b06, T-405, T-8b07, T-8b09, T-8b10, T-304 | K32: ui/, [N] shim launcher :8799 | L32: PK-25, PK-08, PK-06 | M32: PK-25 (dopo contratto API) | N32: La UI non esegue build/test/git (C23–C24).
